<?xml version="1.0" encoding="utf-8"?>
<!-- This URDF was automatically created by SolidWorks to URDF Exporter! Originally created by Stephen Brawner (brawner@gmail.com) 
     Commit Version: 1.6.0-4-g7f85cfe  Build Version: 1.6.7995.38578
     For more information, please see http://wiki.ros.org/sw_urdf_exporter -->
<robot
  name="chopsticks_two">
  <link
    name="Link_1">
    <inertial>
      <origin
        xyz="0.0626852555776957 0.0196504997031689 0.0301495542089222"
        rpy="0 0 0" />
      <mass
        value="0.505174918775633" />
      <inertia
        ixx="0.000302564815061711"
        ixy="1.01044720595202E-06"
        ixz="8.06165852724881E-09"
        iyy="0.00039312506275081"
        iyz="-5.60012256998489E-10"
        izz="0.000466582207237563" />
    </inertial>
    <visual>
      <origin
        xyz="0 0 0"
        rpy="0 0 0" />
      <geometry>
        <mesh
          filename="package://chopsticks_two_description/meshes/Link_1.STL" />
      </geometry>
      <material
        name="">
        <color
          rgba="0.752941176470588 0.752941176470588 0.752941176470588 1" />
      </material>
    </visual>
    <collision>
      <origin
        xyz="0 0 0"
        rpy="0 0 0" />
      <geometry>
        <mesh
          filename="package://chopsticks_two_description/meshes/Link_1.STL" />
      </geometry>
    </collision>
  </link>
  <link
    name="Link_2">
    <inertial>
      <origin
        xyz="-8.0638E-05 0.010417 0.053608"
        rpy="0 0 0" />
      <mass
        value="0.2937" />
      <inertia
        ixx="0.00014913"
        ixy="-4.8763E-08"
        ixz="-1.8942E-08"
        iyy="0.00015543"
        iyz="2.441E-06"
        izz="0.00014802" />
    </inertial>
    <visual>
      <origin
        xyz="0 0 0"
        rpy="0 0 0" />
      <geometry>
        <mesh
          filename="package://chopsticks_two_description/meshes/Link_2.STL" />
      </geometry>
      <material
        name="">
        <color
          rgba="0.75294 0.75294 0.75294 1" />
      </material>
    </visual>
    <collision>
      <origin
        xyz="0 0 0"
        rpy="0 0 0" />
      <geometry>
        <mesh
          filename="package://chopsticks_two_description/meshes/Link_2.STL" />
      </geometry>
    </collision>
  </link>
  <joint
    name="Joint_12"
    type="revolute">
    <origin
      xyz="0 0 0.1023"
      rpy="0 0 0" />
    <parent
      link="Link_1" />
    <child
      link="Link_2" />
    <axis
      xyz="0 0 -1" />
    <limit effort="330" velocity="3" lower="-2.0944" upper="2.0944"/> 
  </joint>
  <link
    name="Link_3">
    <inertial>
      <origin
        xyz="-0.0054615 -0.043424 0.34431"
        rpy="0 0 0" />
      <mass
        value="0.54486" />
      <inertia
        ixx="0.0039997"
        ixy="-1.5784E-08"
        ixz="6.0737E-05"
        iyy="0.0040014"
        iyz="8.8276E-07"
        izz="0.00017244" />
    </inertial>
    <visual>
      <origin
        xyz="0 0 0"
        rpy="0 0 0" />
      <geometry>
        <mesh
          filename="package://chopsticks_two_description/meshes/Link_3.STL" />
      </geometry>
      <material
        name="">
        <color
          rgba="0.75294 0.75294 0.75294 1" />
      </material>
    </visual>
    <collision>
      <origin
        xyz="0 0 0"
        rpy="0 0 0" />
      <geometry>
        <mesh
          filename="package://chopsticks_two_description/meshes/Link_3.STL" />
      </geometry>
    </collision>
  </link>
  <joint
    name="Joint_23"
    type="revolute">
    <origin
      xyz="0 0 0.0570000000000001"
      rpy="0 0 0.0077400490877737" />
    <parent
      link="Link_2" />
    <child
      link="Link_3" />
    <axis
      xyz="0 -1 0" />
    <limit effort="330" velocity="3" lower="0" upper="1.745433"/> 
  </joint>
  <link
    name="Link_4">
    <inertial>
      <origin
        xyz="0.059771 -0.023521 -0.24142"
        rpy="0 0 0" />
      <mass
        value="0.33495" />
      <inertia
        ixx="0.0019607"
        ixy="-7.2625E-09"
        ixz="0.00046379"
        iyy="0.0020737"
        iyz="2.7205E-08"
        izz="0.0002019" />
    </inertial>
    <visual>
      <origin
        xyz="0 0 0"
        rpy="0 0 0" />
      <geometry>
        <mesh
          filename="package://chopsticks_two_description/meshes/Link_4.STL" />
      </geometry>
      <material
        name="">
        <color
          rgba="0.75294 0.75294 0.75294 1" />
      </material>
    </visual>
    <collision>
      <origin
        xyz="0 0 0"
        rpy="0 0 0" />
      <geometry>
        <mesh
          filename="package://chopsticks_two_description/meshes/Link_4.STL" />
      </geometry>
    </collision>
  </link>
  <joint
    name="Joint_34"
    type="revolute">
    <origin
      xyz="-0.00928107122587152 -0.0570821972986843 0.584926372902522"
      rpy="0 -0.015865744635979 0" />
    <parent
      link="Link_3" />
    <child
      link="Link_4" />
    <axis
      xyz="0 -1 0" />
      <limit effort="330" velocity="3" lower="0" upper="2.096706"/>
  </joint>
  <link
    name="Link_5">
    <inertial>
      <origin
        xyz="0.0155515409914033 -0.0046372273869733 -0.0388837787653548"
        rpy="0 0 0" />
      <mass
        value="0.522951900413097" />
      <inertia
        ixx="0.000368393588764988"
        ixy="1.04127804953208E-08"
        ixz="-4.84932910917483E-06"
        iyy="0.000456042697243864"
        iyz="-1.20493463473004E-05"
        izz="0.00048158051785595" />
    </inertial>
    <visual>
      <origin
        xyz="0 0 0"
        rpy="0 0 0" />
      <geometry>
        <mesh
          filename="package://chopsticks_two_description/meshes/Link_5.STL" />
      </geometry>
      <material
        name="">
        <color
          rgba="0.752941176470588 0.752941176470588 0.752941176470588 1" />
      </material>
    </visual>
    <collision>
      <origin
        xyz="0 0 0"
        rpy="0 0 0" />
      <geometry>
        <mesh
          filename="package://chopsticks_two_description/meshes/Link_5.STL" />
      </geometry>
    </collision>
  </link>
  <joint
    name="Joint_45"
    type="revolute">
    <origin
      xyz="0.11655 0 -0.47079"
      rpy="0 -0.40005 0" />
    <parent
      link="Link_4" />
    <child
      link="Link_5" />
    <axis
      xyz="0 1 0" />
    <limit effort="330" velocity="3" lower="-1.5708" upper="1.5708"/>  
  </joint>
  <link
    name="Link_6">
    <inertial>
      <origin
        xyz="-0.002351869106681 -0.000161782865802255 -0.0103380305659397"
        rpy="0 0 0" />
      <mass
        value="0.0638713601202275" />
      <inertia
        ixx="1.5634441298313E-05"
        ixy="-8.58158150492591E-11"
        ixz="-1.20530568164231E-11"
        iyy="2.71302566194123E-05"
        iyz="8.02461778074979E-09"
        izz="2.8253205876481E-05" />
    </inertial>
    <visual>
      <origin
        xyz="0 0 0"
        rpy="0 0 0" />
      <geometry>
        <mesh
          filename="package://chopsticks_two_description/meshes/Link_6.STL" />
      </geometry>
      <material
        name="">
        <color
          rgba="0.752941176470588 0.752941176470588 0.752941176470588 1" />
      </material>
    </visual>
    <collision>
      <origin
        xyz="0 0 0"
        rpy="0 0 0" />
      <geometry>
        <mesh
          filename="package://chopsticks_two_description/meshes/Link_6.STL" />
      </geometry>
    </collision>
  </link>
  <joint
    name="Joint_56"
    type="revolute">
    <origin
      xyz="0 -0.033518 -0.085"
      rpy="-0.017013 0 0" />
    <parent
      link="Link_5" />
    <child
      link="Link_6" />
    <axis
      xyz="1 0 0" />
    <limit effort="330" velocity="3" lower="0" upper="6.28319"/>  
  </joint>
  <link
    name="Gripper">
    <inertial>
      <origin
        xyz="0.0052671 -0.0044673 -0.052262"
        rpy="0 0 0" />
      <mass
        value="0.10828" />
      <inertia
        ixx="0.00012904"
        ixy="-3.7693E-08"
        ixz="2.2958E-06"
        iyy="0.00011742"
        iyz="4.9655E-06"
        izz="2.1257E-05" />
    </inertial>
    <visual>
      <origin
        xyz="0 0 0"
        rpy="0 0 0" />
      <geometry>
        <mesh
          filename="package://chopsticks_two_description/meshes/Gripper.STL" />
      </geometry>
      <material
        name="">
        <color
          rgba="0.75294 0.75294 0.75294 1" />
      </material>
    </visual>
    <collision>
      <origin
        xyz="0 0 0"
        rpy="0 0 0" />
      <geometry>
        <mesh
          filename="package://chopsticks_two_description/meshes/Gripper.STL" />
      </geometry>
    </collision>
  </link>
  <joint
    name="Joint_6G"
    type="revolute">
    <origin
      xyz="-0.00243 0 -0.06033"
      rpy="0 0 0.0089877" />
    <parent
      link="Link_6" />
    <child
      link="Gripper" />
    <axis
      xyz="0 0 -1" />
   <limit effort="330" velocity="3" lower="-1.5708" upper="1.5708"/> 
  </joint>
</robot>
